<?xml version="1.0" ?>

<robot name="pulsar">

  <!-- Colors -->
  <material name="Grey">
      <color rgba="0.2 0.2 0.2 1.0"/>
  </material>
  <material name="Orange">
      <color rgba="1.0 0.4 0.3 1.0"/>
  </material>
  <material name="Blue">
  <color rgba="0.5 0.7 1.0 1.0"/>
  </material>
  <material name="Red">
      <color rgba="1 0 0 1.0"/>
  </material>

<!-- ********************************************************** -->


  <!--Spacecraft-->
  <link name="Spacecraft">
      <inertial>
      <origin rpy="0 0 0" xyz="0.9 0 0"/>
      <mass value="1960"/>
      <inertia ixx="3345" ixy="0" ixz="0" iyy="2202" iyz="0" izz="2202"/>
      </inertial>
      <visual>
      <origin xyz="1 0 0" rpy="0 -1.57075 0"/>
      <geometry>
          <cylinder length="2" radius="1.6"/>
      </geometry>
      <material name="Orange"/>
    </visual>
    <stiffness name="rigid"/>
  </link>

  <!-- Joint to Payload -->
<joint name="Spacecraft_Payload" type="fixed">
    <parent link="Spacecraft"/>
    <child link="Payload"/>
    <origin xyz="3.75 0 0" rpy="0 0 0" />
    <axis xyz="1 0 0"/>
</joint>

  <!--Payload-->
  <link name="Payload">
      <inertial>
      <origin xyz="0.55 0 0"/>
      <mass value="1440"/>
      <inertia ixx="2458" ixy="0" ixz="0" iyy="1499" iyz="0" izz="1499"/>
      </inertial>
      <visual>
      <origin xyz="0 0 0" rpy="0 -1.57075 0"/>
      <geometry>
          <cylinder length="1.5" radius="1.6"/>
      </geometry>
      <material name="Blue"/>
      </visual>
      <stiffness name="rigid"/>
  </link>

<!-- ********************************************************** -->
  <!--joint Spacecraft to Reaction Wheel 1 -->
    <joint name="Spacecraft_to_RW1" type="revolute">
        <parent link="Spacecraft" />
        <child link="RW1"/>
        <origin xyz="0 0  0" rpy="pi/2 0 0" />
        <!-- <origin xyz="0 0  0" rpy="35.2644*pi/180 pi/4 0" /> -->
        <axis xyz="0 0 1"/>
        <limit effort="1000.0" lower="0" upper="0" velocity="0"/>
    </joint>

    <!-- Reaction Wheel 1 -->
    <link name="RW1" >
      <inertial>
          <origin rpy ="0 0 0" xyz="0 0 0.0" />
          <mass value="4"/>
          <inertia ixx="0.065" ixy="0" ixz="0" iyy="0.065" iyz="0" izz="0.2125"/>
      </inertial>
      <visual>
          <origin rpy="0 0 0" xyz="0 0 0"/>
          <geometry>
            <cylinder length="0.16/2" radius="0.31/2" />
          </geometry>
          <material name="Grey"/>
      </visual>
    <stiffness name="rigid"/>
    </link>

    <!--joint Spacecraft to Reaction Wheel 2 -->
    <joint name="Spacecraft_to_RW2" type="revolute">
        <parent link="Spacecraft" />
        <child link="RW2"/>
        <origin xyz="0 0 0" rpy="0 pi/2 0" />
        <!-- <origin xyz="0 0 0" rpy="35.2644*pi/180 3*pi/4 0" /> -->
        <axis xyz="0 0 1"/>
        <limit effort="1000.0" lower="0" upper="0" velocity="0"/>
    </joint>

    <!-- Reaction Wheel 2 -->
    <link name="RW2" >
      <inertial>
          <origin rpy ="0 0 0" xyz="0 0 0.0" />
          <mass value="4"/>
          <inertia ixx="0.065" ixy="0" ixz="0" iyy="0.065" iyz="0" izz="0.2125"/>
      </inertial>
      <visual>
          <origin rpy="0 0 0" xyz="0 0 0"/>
          <geometry>
            <cylinder length="0.16/2" radius="0.31/2" />
          </geometry>
          <material name="Grey"/>
      </visual>
    <stiffness name="rigid"/>
    </link>

    <!--joint Spacecraft to Reaction Wheel 3-->
    <joint name="Spacecraft_to_RW3" type="revolute">
        <parent link="Spacecraft" />
        <child link="RW3"/>
        <origin xyz="0 0 0" rpy="0 0 pi/2" />
        <!-- <origin xyz="0 0 0" rpy="-35.2644*pi/180 3*pi/4 0" /> -->
        <axis xyz="0 0 1"/>
        <limit effort="1000.0" lower="0" upper="0" velocity="0"/>
    </joint>

    <!-- Reaction Wheel 3 -->
    <link name="RW3" >
    <inertial>
        <origin rpy ="0 0 0" xyz="0 0 0.0" />
        <mass value="4"/>
        <inertia ixx="0.065" ixy="0" ixz="0" iyy="0.065" iyz="0" izz="0.2125"/>
    </inertial>
    <visual>
        <origin rpy="0 0 0" xyz="0 0 0"/>
        <geometry>
          <cylinder length="0.16/2" radius="0.31/2" />
        </geometry>
        <material name="Grey"/>
    </visual>
    <stiffness name="rigid"/>
    </link>

    

<!-- ********************************************************** -->

      <!-- Joint to Left Solar Panel -->
    <joint name="Spacecraft_Left_Panel" type="fixed">
        <parent link="Spacecraft"/>
        <child link="Left_Panel"/>
        <origin xyz="1 0 -1.6" rpy="3.1416 0 0"/>
        <axis xyz="1 0 0"/>
    </joint>

    <!-- Left Solar Panel-->
    <link name="Left_Panel">
        <inertial>
        <origin rpy="0 0 0" xyz="0.001 0.001 3.8447"/>
        <mass value="61"/>
        <inertia ixx="17" ixy="0" ixz="0" iyy="1250" iyz="0" izz="1233"/>
        </inertial>
        <visual>
        <origin rpy="0 0 0" xyz="0 0 2.75"/>
        <geometry>
            <box size="0.25 2 5.5"/>
        </geometry>
        <material name="Blue"/>
        </visual>
        <stiffness name="rigide">
      </stiffness>
    </link>

    <!-- Joint to Right Solar Panel -->
    <joint name="Spacecraft_Right_Panel" type="fixed">
        <parent link="Spacecraft"/>
        <child link="Right_Panel"/>
        <origin xyz="1 0 1.6" rpy="0 0 0"/>
        <axis xyz="1 0 0"/>
    </joint>

    <!-- Right Solar Panel-->
    <link name="Right_Panel">
      <inertial>
      <origin rpy="0 0 0" xyz="0.001 0.001 3.8447"/>
      <mass value="61"/>
      <inertia ixx="17" ixy="0" ixz="0" iyy="1250" iyz="0" izz="1233"/>
      </inertial>
      <visual>
      <origin rpy="0 0 0" xyz="0 0 2.75"/>
      <geometry>
          <box size="0.25 2 5.5"/>
      </geometry>
      <material name="Blue"/>
      </visual>
      <stiffness name="rigide">
      </stiffness>
    </link>




 <!-- ********************************************************** -->

<!-- Vispa Arm  1-->


  <joint name="base_link-link1" type="fixed">
    <parent link="Spacecraft"/>
    <child link="Link_0_"/>
    <origin xyz="4.5 0 -1.07" rpy="pi -pi/2 0"/>
    <limit effort="1000.0" lower="0" upper="0" velocity="0"/>
    <!-- <origin xyz="0 0 0" rpy="0 0 ${2*C_1_DEGREE}"/> -->
  </joint>

  <link name="Link_0_">
    <visual>
      <geometry>
        <mesh filename="meshes/Link0-DHReference-PublicRelease.stl"/>
      </geometry>
    </visual>
    <inertial>
      <mass value="0.627"/>
      <inertia ixx="0.00281845585208" ixy="0" ixz="0" iyy="0.00281883333333" iyz="0" izz="0.00379978918542"/>
      <origin xyz="0 0 0.0"/>
    </inertial>
    <stiffness name="rigid"/>
  </link>

   
  <joint name="Joint_1_" type="revolute">
    <parent link="Link_0_"/>
    <child link="Link_1_"/>
    <axis xyz="0 0 1"/>
    <limit effort="50" lower="-3.14149265359" upper="3.14149265359" velocity="0.09395689"/>
    <origin xyz="0 0 0.18" rpy="0 0 0"/>
  </joint>

  <link name="Link_1_">
    <visual>
      <geometry>
        <mesh filename="meshes/Link1-DHReference-PublicRelease.stl"/>
      </geometry>
    </visual>
    <inertial>
      <mass value="2.328"/>
      <inertia ixx="0.012" ixy="0" ixz="0" iyy="0.007" iyz="0.003" izz="0.008"/>
      <origin xyz="0 -0.029 -0.043"/>
    </inertial>    
    <stiffness name="rigid"/>
  </link>


  <joint name="Joint_2_" type="revolute">
    <parent link="Link_1_"/>
    <child link="Link_2_"/>
    <axis xyz="0 0 1"/>
    <limit effort="50" lower="-3.14149265359" upper="3.14149265359" velocity="0.09395689"/>
    <origin xyz="0 0 0" rpy="1.57079632679 -1.57079632679 0"/>
  </joint>

 <link name="Link_2_">
    <visual>
      <geometry>
        <mesh filename="meshes/Link2-DHReference-PublicRelease.stl"/>
      </geometry>
    </visual>
    <inertial>
      <mass value="3.995"/>
      <inertia ixx="0.010" ixy="0" ixz="0" iyy="0.578" iyz="0" izz="0.574"/>
      <origin xyz="0.4 0 0.142"/>
    </inertial>
    <stiffness name="rigid"/>
  </link>

 <joint name="Joint_3_" type="revolute">
    <parent link="Link_2_"/>
    <child link="Link_3_"/>
    <axis xyz="0 0 1"/>
    <limit effort="50" lower="-3.14149265359" upper="3.14149265359" velocity="0.09395689"/>
    <origin xyz="0.8 0 0" rpy="0 0 -1.57079632679"/>
  </joint>

  <link name="Link_3_">
    <visual>
      <geometry>
        <mesh filename="meshes/Link3-DHReference-PublicRelease.stl"/>
      </geometry>
    </visual>
    <inertial>
      <mass value="2.328"/>
      <inertia ixx="0.012" ixy="0" ixz="0" iyy="0.008" iyz="0.003" izz="0.007"/>
      <origin xyz="0 0.043 0.029"/>
    </inertial>
    <stiffness name="rigid"/>
  </link>

<joint name="Joint_4_" type="revolute">
    <parent link="Link_3_"/>
    <child link="Link_4_"/>
    <axis xyz="0 0 1"/>
    <limit effort="50" lower="-3.14149265359" upper="3.14149265359" velocity="0.09395689"/>
    <origin xyz="0 0.65 0" rpy="-1.57079632679 0 0"/>
  </joint>


  <link name="Link_4_">
    <visual>
      <geometry>
        <mesh filename="meshes/Link4-DHReference-PublicRelease.stl"/>
      </geometry>
    </visual>
    <inertial>
      <mass value="3.157"/>
      <inertia ixx="0.199" ixy="0" ixz="0" iyy="0.193" iyz="0.01" izz="0.01"/>
      <origin xyz="0 -0.043 -0.210"/>
    </inertial>
    <stiffness name="rigid"/>
  </link>

 <joint name="Joint_5_" type="revolute">
    <parent link="Link_4_"/>
    <child link="Link_5_"/>
    <axis xyz="0 0 1"/>
    <limit effort="50" lower="-3.14149265359" upper="3.14149265359" velocity="0.09395689"/>
    <origin xyz="0 0 0" rpy="1.57079632679 0 0"/>
  </joint>


  <link name="Link_5_">
    <visual>
      <geometry>
        <mesh filename="meshes/Link5-DHReference-PublicRelease.stl"/>
      </geometry>
    </visual>
    <inertial>
      <mass value="2.695"/>
      <inertia ixx="0.029" ixy="0" ixz="0" iyy="0.006" iyz="-0.001" izz="0.027"/>
      <origin xyz="0 0.125 -0.007"/>
    </inertial>
    <stiffness name="rigid"/>
  </link>

  
 
  <joint name="Joint_6_" type="fixed">
    <parent link="Link_5_"/>
    <child link="Link_EE"/>
    <axis xyz="0 0 1"/>
    <limit effort="50" lower="-3.14149265359" upper="3.14149265359" velocity="0.09395689"/>
    <origin xyz="0 0.325 0" rpy="-1.57079632679 0 0"/>
  </joint>

  <link name="Link_EE">
    <visual>
      <geometry>
        <mesh filename="meshes/Link6-DHReference-PublicRelease.stl"/>
      </geometry>
    </visual>
    <inertial>
      <mass value="300"/> <!--0.924-->
      <inertia ixx="0.002" ixy="0" ixz="0" iyy="0.002" iyz="0" izz="0.001"/>
      <origin xyz="0 0 0.0"/>
    </inertial>
    <stiffness name="rigid"/>
  </link>


</robot>
