<?xml version="1.0" ?>

<robot name="pulsar">

  <!-- Colors -->
  <material name="Grey">
      <color rgba="0.2 0.2 0.2 1.0"/>
  </material>
  <material name="Orange">
      <color rgba="1.0 0.4 0.3 1.0"/>
  </material>
  <material name="Blue">
  <color rgba="0.5 0.7 1.0 1.0"/>
  </material>
  <material name="Red">
      <color rgba="1 0 0 1.0"/>
  </material>

<!-- ********************************************************** -->


  <!--Spacecraft-->
  <link name="Spacecraft">
      <inertial>
      <origin rpy="0 0 0" xyz="0 0 0"/>
      <mass value="1960"/>
      <inertia ixx="3345" ixy="0" ixz="0" iyy="2202" iyz="0" izz="2202"/>
      </inertial>
      <visual>
      <origin xyz="0.1 0 0" rpy="0 -1.57075 0"/>
      <geometry>
          <cylinder length="2" radius="1.6"/>
      </geometry>
      <material name="Orange"/>
    </visual>
    <stiffness name="rigid"/>
  </link>

  <!-- Joint to Payload -->
<joint name="Spacecraft_Payload" type="fixed">
    <parent link="Spacecraft"/>
    <child link="Payload"/>
    <origin xyz="1.1 0 0" rpy="0 0 0" />
    <axis xyz="1 0 0"/>
</joint>

  <!--Payload-->
  <link name="Payload">
      <inertial>
      <origin xyz="1.45 0 0"/>
      <mass value="1440"/>
      <inertia ixx="2458" ixy="0" ixz="0" iyy="1499" iyz="0" izz="1499"/>
      </inertial>
      <visual>
      <origin xyz="0.75 0 0" rpy="0 -1.57075 0"/>
      <geometry>
          <cylinder length="1.5" radius="1.6"/>
      </geometry>
      <material name="Blue"/>
      </visual>
      <stiffness name="rigid"/>
  </link>

  <!-- ********************************************************** -->

  <!-- Joint to Sun-Shield Beam 1-->
<joint name="Spacecraft_Sun_shield_B1" type="fixed">
    <parent link="Spacecraft"/>
    <child link="Sun_shield_B1"/>
    <origin xyz="1.3 0 1.6" rpy="0 0 0"/>
    <axis xyz="1 0 0"/>
</joint>

<!-- Sun shield Beam 1-->
<link name="Sun_shield_B1">
    <inertial>
    <origin rpy="0 0 0" xyz="0.0 0.0 7"/>
    <mass value="70"/>
    <inertia ixx="940" ixy="0" ixz="0" iyy="920" iyz="0" izz="25"/>
    </inertial>
    <visual>
    <origin rpy="0 0 0" xyz="0 0 5.6"/>
    <geometry>
        <cylinder length="11.2" radius="0.2"/>/>
    </geometry>
    <material name="Blue"/>
    </visual>
    <stiffness name="flexible">
      <mode_number value="1"/>
      <mode_1 pulse="2.24*2*pi" L="0 -6.6 0.1 15.3 0 0.2" damp="0.005"/>
      <mode_2 pulse="7.07*2*pi" L="-6.7 0 -0.1 0 -15.4 0.4" damp="0.005"/>
      <mode_3 pulse="13.84*2*pi" L="0 -3.5 0.7 1.7 0 0.1" damp="0.005"/>
    </stiffness>
</link>

<!-- Joint to Sun-Shield Beam 2-->
<joint name="Spacecraft_Sun_shield_B2" type="fixed">
  <parent link="Spacecraft"/>
  <child link="Sun_shield_B2"/>
  <origin xyz="1.3 -1.6 0" rpy="1.5708 0 0"/>
  <axis xyz="1 0 0"/>
</joint>

<!-- Sun shield Beam 2-->
<link name="Sun_shield_B2">
    <inertial>
    <origin rpy="0 0 0" xyz="0.0 0.0 10.4"/>
    <mass value="80"/>
    <inertia ixx="1640" ixy="0" ixz="0" iyy="1620" iyz="0" izz="30"/>
    </inertial>
    <visual>
    <origin rpy="0 0 0" xyz="0 0 7.1"/>
    <geometry>
        <cylinder length="14.2" radius="0.2"/>/>
    </geometry>
    <material name="Blue"/>
    </visual>
    <stiffness name="flexible">
      <mode_number value="2"/>
      <mode_1 pulse="2.24*2*pi" L="0 -6.6 0.1 15.3 0 0.2" damp="0.005"/>
      <mode_2 pulse="7.07*2*pi" L="-6.7 0 -0.1 0 -15.4 0.4" damp="0.005"/>
      <mode_3 pulse="13.84*2*pi" L="0 -3.5 0.7 1.7 0 0.1" damp="0.005"/>
    </stiffness>
</link>

<!-- Joint to Sun-Shield Beam 3-->
<joint name="Spacecraft_Sun_shield_B3" type="fixed">
  <parent link="Spacecraft"/>
  <child link="Sun_shield_B3"/>
  <origin xyz="1.3 0 -1.6" rpy="3.1416 0 0"/>
  <axis xyz="1 0 0"/>
</joint>

<!-- Sun shield Beam 3-->
<link name="Sun_shield_B3">
    <inertial>
      <origin rpy="0 0 0" xyz="0.0 0.0 7"/>
      <mass value="70"/>
      <inertia ixx="940" ixy="0" ixz="0" iyy="920" iyz="0" izz="25"/>
      </inertial>
      <visual>
      <origin rpy="0 0 0" xyz="0 0 5.6"/>
      <geometry>
          <cylinder length="11.2" radius="0.2"/>/>
      </geometry>
    <material name="Blue"/>
    </visual>
    <stiffness name="flexible">
      <mode_number value="1"/>
      <mode_1 pulse="2.24*2*pi" L="0 -6.6 0.1 15.3 0 0.2" damp="0.005"/>
      <mode_2 pulse="7.07*2*pi" L="-6.7 0 -0.1 0 -15.4 0.4" damp="0.005"/>
      <mode_3 pulse="13.84*2*pi" L="0 -3.5 0.7 1.7 0 0.1" damp="0.005"/>
    </stiffness>
</link>

<!-- Joint to Sun-Shield Beam 4-->
<joint name="Spacecraft_Sun_shield_B4" type="fixed">
  <parent link="Spacecraft"/>
  <child link="Sun_shield_B4"/>
  <origin xyz="1.3 1.6 0" rpy="-1.5708 0 0"/>
  <axis xyz="1 0 0"/>
</joint>

<!-- Sun shield Beam 4-->
<link name="Sun_shield_B4">
    <inertial>
      <origin rpy="0 0 0" xyz="0.0 0.0 10.4"/>
      <mass value="80"/>
      <inertia ixx="1640" ixy="0" ixz="0" iyy="1620" iyz="0" izz="30"/>
      </inertial>
      <visual>
      <origin rpy="0 0 0" xyz="0 0 7.1"/>
      <geometry>
          <cylinder length="14.2" radius="0.2"/>/>
      </geometry>
    <material name="Blue"/>
    </visual>
    <stiffness name="flexible">
      <mode_number value="1"/>
      <mode_1 pulse="2.24*2*pi" L="0 -6.6 0.1 15.3 0 0.2" damp="0.005"/>
      <mode_2 pulse="7.07*2*pi" L="-6.7 0 -0.1 0 -15.4 0.4" damp="0.005"/>
      <mode_3 pulse="13.84*2*pi" L="0 -3.5 0.7 1.7 0 0.1" damp="0.005"/>
    </stiffness>
</link>

<!-- ********************************************************** -->

      <!-- Joint to Left Solar Panel -->
    <joint name="Spacecraft_Left_Panel" type="fixed">
        <parent link="Spacecraft"/>
        <child link="Left_Panel"/>
        <origin xyz="-0.9 0 -1.6" rpy="3.1416 0 0"/>
        <axis xyz="1 0 0"/>
    </joint>

    <!-- Left Solar Panel-->
    <link name="Left_Panel">
        <inertial>
        <origin rpy="0 0 0" xyz="0.001 0.001 3.8447"/>
        <mass value="61"/>
        <inertia ixx="17" ixy="0" ixz="0" iyy="1250" iyz="0" izz="1233"/>
        </inertial>
        <visual>
        <origin rpy="0 0 0" xyz="0 0 2.75"/>
        <geometry>
            <box size="0.25 2 5.5"/>
        </geometry>
        <material name="Blue"/>
        </visual>
        <stiffness name="flexible">
          <mode_number value="1"/>
          <mode_1 pulse="0.16*2*pi" L="-6.4 0 0 0 -35 0" damp="0.005"/>
          <mode_2 pulse="0.70*2*pi" L="0 -6.7 0 35.4 0 0" damp="0.005"/>
          <mode_3 pulse="1.08*2*pi" L="-0.1 -0.1 0 0.3 0 3.8" damp="0.005"/>
          <mode_4 pulse="1.21*2*pi" L="-3.2 0 0 0 -3 -0.01" damp="0.005"/>
          <mode_5 pulse="3.05*2*pi" L="2.3 0 -0.3 0 1.3 0" damp="0.005"/>
        </stiffness>
    </link>

    <!-- Joint to Right Solar Panel -->
    <joint name="Spacecraft_Right_Panel" type="fixed">
        <parent link="Spacecraft"/>
        <child link="Right_Panel"/>
        <origin xyz="-0.9 0 1.6" rpy="0 0 0"/>
        <axis xyz="1 0 0"/>
    </joint>

    <!-- Right Solar Panel-->
    <link name="Right_Panel">
      <inertial>
      <origin rpy="0 0 0" xyz="0.001 0.001 3.8447"/>
      <mass value="61"/>
      <inertia ixx="17" ixy="0" ixz="0" iyy="1250" iyz="0" izz="1233"/>
      </inertial>
      <visual>
      <origin rpy="0 0 0" xyz="0 0 2.75"/>
      <geometry>
          <box size="0.25 2 5.5"/>
      </geometry>
      <material name="Blue"/>
      </visual>
      <stiffness name="flexible">
        <mode_number value="3"/>
        <mode_1 pulse="0.16*2*pi" L="-6.4 0 0 0 -35 0" damp="0.005"/>
        <mode_2 pulse="0.70*2*pi" L="0 -6.7 0 35.4 0 0" damp="0.005"/>
        <mode_3 pulse="1.08*2*pi" L="-0.1 -0.1 0 0.3 0 3.8" damp="0.005"/>
        <mode_4 pulse="1.21*2*pi" L="-3.2 0 0 0 -3 -0.01" damp="0.005"/>
        <mode_5 pulse="3.05*2*pi" L="2.3 0 -0.3 0 1.3 0" damp="0.005"/>
      </stiffness>
    </link>

    <!-- ********************************************************** -->

    <!-- Joint to stack1 -->
     <joint name="Payload_stack1" type="fixed">
         <parent link="Payload"/>
         <child link="stack1"/>
         <origin xyz="1.5 0 0" rpy="0 0 0"/>
         <axis xyz="1 0 0"/>
     </joint>

     <!-- stack1-->
     <link name="stack1">
         <inertial>
         <origin xyz="1.5 1.5 0" rpy="0 0 0"/>
         <mass value="263"/>
         <inertia ixx="61" ixy="0" ixz="0" iyy="226" iyz="0" izz="226"/>
         </inertial>
         <visual>
           <origin rpy="0 0 0" xyz="1.5 1.5 0"/>
             <mesh filename="stack.stl"/>
         <material name="Red"/>
         </visual>
         <stiffness name="rigid"/>
     </link>



           <!-- ********************************************************** -->

           <!-- Joint to Mast-->
         <joint name="Spacecraft_Mast" type="fixed">
             <parent link="Spacecraft"/>
             <child link="Mast"/>
             <origin xyz="5.4 0 0" rpy="0 0 0"/>
             <axis xyz="1 0 0"/>
         </joint>

         <!-- Mast-->
         <link name="Mast">
             <inertial>
             <origin xyz="0.0 0.0 0.0" rpy="0 0 0"/>
             <mass value="1132"/>
             <inertia ixx="307" ixy="0" ixz="0" iyy="3490" iyz="0" izz="3608"/>
             </inertial>
             <visual>
             <origin rpy="0 0 0" xyz="0 0 0"/>
             <geometry>
                 <box size="6 1.5 1"/>
             </geometry>
             <material name="Blue"/>
             </visual>
             <stiffness name="rigid"/>
         </link>

         <!-- Joint to Instrument-->
       <joint name="Spacecraft_Instrument" type="fixed">
           <parent link="Spacecraft"/>
           <child link="Instrument"/>
           <origin xyz="7.85 0 -1.25" rpy="0 0 0"/>
           <axis xyz="1 0 0"/>
       </joint>

       <!-- Instrument-->
       <link name="Instrument">
           <inertial>
           <origin xyz="0.0 0.0 0.0" rpy="0 0 0"/>
           <mass value="450"/>
           <inertia ixx="169" ixy="0" ixz="0" iyy="169" iyz="0" izz="169"/>
           </inertial>
           <visual>
           <origin rpy="0 0 0" xyz="0 0 0"/>
           <geometry>
               <box size="1.5 1.5 1.5"/>
           </geometry>
           <material name="Blue"/>
           </visual>
           <stiffness name="rigid"/>
       </link>

       <!-- Joint to Master_Tile-->
     <joint name="Spacecraft_Master_Tile" type="fixed">
         <parent link="Spacecraft"/>
         <child link="Master_Tile"/>
         <origin xyz="7.55 0 0.875" rpy="0 0 0"/>
         <axis xyz="1 0 0"/>
     </joint>

     <!-- Master_Tile-->
     <link name="Master_Tile">
         <inertial>
         <origin xyz="0.0 0.0 0.0" rpy="0 0 0"/>
         <mass value="50"/>
         <inertia ixx="12" ixy="0" ixz="0" iyy="12" iyz="0" izz="19"/>
         </inertial>
         <visual>
         <origin rpy="0 0 0" xyz="0 0 0"/>
         <geometry>
             <mesh filename="master_tileb.stl"/>
         </geometry>
         <material name="Blue"/>
         </visual>
         <stiffness name="rigid"/>
     </link>

     <!-- Joint to Second_Mirror-->
   <joint name="Spacecraft_Second_Mirror" type="fixed">
       <parent link="Spacecraft"/>
       <child link="Second_Mirror"/>
       <origin xyz="9.6 0 -1" rpy="0 0 0"/>
       <axis xyz="1 0 0"/>
   </joint>

   <!-- Instrument-->
   <link name="Second_Mirror">
       <inertial>
       <origin xyz="0.0 0.0 0.0" rpy="0 0 0"/>
       <mass value="161"/>
       <inertia ixx="44" ixy="0" ixz="0" iyy="67" iyz="0" izz="84"/>
       </inertial>
       <visual>
       <origin rpy="0 0 0" xyz="0 0 0"/>
       <geometry>
           <box size="2 1.5 1"/>
       </geometry>
       <material name="Blue"/>
       </visual>
       <stiffness name="rigid"/>
   </link>


     <!-- ********************************************************** -->
     <!-- Joint to Pre-assembly -->
     <joint name="Master_Tile_Pre_asm" type="fixed">
         <parent link="Master_Tile"/>
         <child link="Pre_asm"/>
         <origin xyz="0 0 -0.875" rpy="0 0 0"/>
         <axis xyz="1 0 0"/>
     </joint>

     <!-- Pre_asm -->
     <link name="Pre_asm">
         <inertial>
         <origin rpy="0 0 0" xyz="0 0 0"/>
         <mass value="0"/>
         <inertia ixx="0" ixy="0" ixz="0" iyy="0" iyz="0" izz="0"/>
         </inertial>
         <visual>
         <origin xyz="1.3125 0 0" rpy="0 0 0" />
         <geometry>
             <box size="2.625 3.9 0.4"/>
         </geometry>
         <material name="Grey"/>
         </visual>
         <stiffness name="rigid"/>
     </link>

          <!-- ********************************************************** -->
          <!-- Joint to Mirror -->
          <joint name="Master_Tile_Mirror" type="fixed">
              <parent link="Master_Tile"/>
              <child link="Mirror"/>
              <origin xyz="0 0 0" rpy="0 0 0" />
              <axis xyz="1 0 0"/>
          </joint>

          <!-- Mirror -->
          <link name="Mirror">
              <inertial>
              <origin rpy="0 0 0" xyz="0 0 0"/>
              <mass value="0"/>
              <inertia ixx="0" ixy="0" ixz="0" iyy="0" iyz="0" izz="0"/>
              </inertial>
              <visual>
              <origin rpy="0 0 0" xyz="0 0 0"/>
              <geometry>
                  <cylinder length="0.7" radius="4.2"/>
              </geometry>
              <material name="Blue"/>
              </visual>
              <stiffness name="rigid"/>
          </link>

  <!-- ********************************************************** -->
  <!--joint Spacecraft to Reaction Wheel 1 -->
    <joint name="Spacecraft_to_RW1" type="revolute">
        <parent link="Spacecraft" />
        <child link="RW1"/>
        <origin xyz="-0.4 -0.5  0.5" rpy="35.2644*pi/180 pi/4 0" />
        <axis xyz="0 0 1"/>
        <limit effort="1000.0" lower="0" upper="0" velocity="0"/>
    </joint>

    <!-- Reaction Wheel 1 -->
    <link name="RW1" >
      <inertial>
          <origin rpy ="0 0 0" xyz="0 0 0.0" />
          <mass value="4"/>
          <inertia ixx="0.065" ixy="0" ixz="0" iyy="0.065" iyz="0" izz="0.1322"/>
      </inertial>
      <visual>
          <origin rpy="0 0 0" xyz="0 0 0"/>
          <geometry>
            <cylinder length="0.16" radius="0.31" />
          </geometry>
          <material name="Grey"/>
      </visual>
    <stiffness name="rigid"/>
    </link>

    <!--joint Spacecraft to Reaction Wheel 2 -->
    <joint name="Spacecraft_to_RW2" type="revolute">
        <parent link="Spacecraft" />
        <child link="RW2"/>
        <origin xyz="-0.4 -0.5 -0.5" rpy="35.2644*pi/180 3*pi/4 0" />
        <axis xyz="0 0 1"/>
        <limit effort="1000.0" lower="0" upper="0" velocity="0"/>
    </joint>

    <!-- Reaction Wheel 2 -->
    <link name="RW2" >
      <inertial>
          <origin rpy ="0 0 0" xyz="0 0 0.0" />
          <mass value="4"/>
          <inertia ixx="0.065" ixy="0" ixz="0" iyy="0.065" iyz="0" izz="0.1322"/>
      </inertial>
      <visual>
          <origin rpy="0 0 0" xyz="0 0 0"/>
          <geometry>
            <cylinder length="0.16" radius="0.31" />
          </geometry>
          <material name="Grey"/>
      </visual>
    <stiffness name="rigid"/>
    </link>

    <!--joint Spacecraft to Reaction Wheel 3-->
    <joint name="Spacecraft_to_RW3" type="revolute">
        <parent link="Spacecraft" />
        <child link="RW3"/>
        <origin xyz="-0.4 0.5 -0.5" rpy="-35.2644*pi/180 3*pi/4 0" />
        <axis xyz="0 0 1"/>
        <limit effort="1000.0" lower="0" upper="0" velocity="0"/>
    </joint>

    <!-- Reaction Wheel 3 -->
    <link name="RW3" >
    <inertial>
        <origin rpy ="0 0 0" xyz="0 0 0.0" />
        <mass value="4"/>
        <inertia ixx="0.065" ixy="0" ixz="0" iyy="0.065" iyz="0" izz="0.1322"/>
    </inertial>
    <visual>
        <origin rpy="0 0 0" xyz="0 0 0"/>
        <geometry>
          <cylinder length="0.16" radius="0.31" />
        </geometry>
        <material name="Grey"/>
    </visual>
    <stiffness name="rigid"/>
    </link>

    <!--joint Spacecraft to Reaction Wheel 4-->
    <joint name="Spacecraft_to_RW4" type="revolute">
        <parent link="Spacecraft" />
        <child link="RW4"/>
        <origin xyz="-0.4 0.5 0.5" rpy="-35.2644*pi/180 pi/4 0" />
        <axis xyz="0 0 1"/>
        <limit effort="1000.0" lower="0" upper="0" velocity="0"/>
    </joint>

    <!-- Reaction Wheel 4 -->
    <link name="RW4" >
      <inertial>
          <origin rpy ="0 0 0" xyz="0 0 0.0" />
          <mass value="4"/>
          <inertia ixx="0.065" ixy="0" ixz="0" iyy="0.065" iyz="0" izz="0.1322"/>
      </inertial>
      <visual>
          <origin rpy="0 0 0" xyz="0 0 0"/>
          <geometry>
            <cylinder length="0.16" radius="0.31" />
          </geometry>
          <material name="Grey"/>
      </visual>
    <stiffness name="rigid"/>
    </link>

 <!-- ********************************************************** -->

<!--joint between {parent} and link_0-->
 <joint name="Spacecraft_rail_joint" type="fixed">
   <origin rpy="-1.57075 0 0" xyz="3.5 0 0"/>
   <parent link="Spacecraft"/>
   <child link="rail_link_0"/>
 </joint>

 <link name="rail_link_0">
   <inertial>
     <origin rpy="0 0 0" xyz="2.65 0 0"/>
     <mass value="234.09894105"/>
     <inertia ixx="0.001" ixy="0" ixz="0" iyy="0.001" iyz="0" izz="0.001"/>
   </inertial>
   <visual>
     <origin rpy="0 0 0" xyz="0 0 0"/>
     <geometry>
       <mesh filename="meshes_dISAS/rail/rail_base.dae"/>
     </geometry>
     <material name="Grey"/>
   </visual>
   <stiffness name="rigid"/>
 </link>


 <!-- joint between link_0 and link_1 -->
<!--  <joint name="rail_joint_1" type="prismatic"> -->
  <joint name="rail_joint_1" type="prismatic">   
   <parent link="rail_link_0"/>
   <child link="rail_link_1"/>
   <origin rpy="0 0 0" xyz="0.15 0 0.15"/>
   <axis xyz="1 0 0"/>
   <limit effort="10000" lower="0.0" upper="5.0" velocity="1"/>
 </joint>
 <link name="rail_link_1">
   <inertial>
     <origin rpy="0 0 0" xyz="0 0 0"/>
     <mass value="15.90105894"/>
     <inertia ixx="0.001" ixy="0" ixz="0" iyy="0.001" iyz="0" izz="0.001"/>
   </inertial>
   <visual>
     <origin rpy="0 0 0" xyz="0 0 0"/>
     <geometry>
       <mesh filename="meshes_dISAS/rail/rail_slot.dae"/>
     </geometry>
     <material name="Grey"/>
   </visual>
   <stiffness name="rigid"/>
 </link>

 <!--joint between {parent} and link_0-->
 <joint name="rail_link_1_arm_joint" type="fixed">
   <origin rpy="0 0 0" xyz="0 0 0.05"/>
   <parent link="rail_link_1"/>
   <child link="arm_link_0"/>
 </joint>
 <link name="arm_link_0">
   <inertial>
     <origin rpy="0 0 0" xyz="0 0 0.0318"/>
     <mass value="7"/>
     <inertia ixx="0.01" ixy="0" ixz="0" iyy="0.01" iyz="0" izz="0.08"/>
   </inertial>
   <visual>
     <origin rpy="0 0 0" xyz="0 0 0"/>
     <geometry>
       <mesh filename="meshes_dISAS/arm/link_0.dae"/>
     </geometry>
     <material name="Grey"/>
   </visual>
   <stiffness name="rigid"/>
 </link>



 <!-- joint between link_0 and link_1 -->
<!-- <joint name="arm_joint_1" type="revolute"> -->
<joint name="arm_joint_1" type="revolute">
   <parent link="arm_link_0"/>
   <child link="arm_link_1"/>
   <origin rpy="0 0 0" xyz="0 0 0.0635"/>
   <axis xyz="0 0 1"/>
   <limit effort="5000" lower="-3.14159265359" upper="3.14159265359" velocity="3"/>
   <safety_controller k_position="100" k_velocity="2" soft_lower_limit="-3.10668606855" soft_upper_limit="3.28121899375"/>
   <dynamics damping="0.5"/>
 </joint>
 <link name="arm_link_1">
   <inertial>
     <origin rpy="0 0 0" xyz="0 0 0.0888"/>
     <mass value="7"/>
     <inertia ixx="0.021" ixy="0" ixz="0" iyy="0.021" iyz="0" izz="0.01"/>
   </inertial>
   <visual>
     <origin rpy="0 0 0" xyz="0 0 0"/>
     <geometry>
       <mesh filename="meshes_dISAS/arm/link_1.dae"/>
     </geometry>
     <material name="Grey"/>
   </visual>
   <stiffness name="rigid"/>
 </link>                    


 <!-- joint between link_1 and link_2 | 1_T_2 -->
<!-- <joint name="arm_joint_2" type="revolute">  -->
<joint name="arm_joint_2" type="revolute">
   <parent link="arm_link_1"/>
   <child link="arm_link_2"/>
   <origin rpy="-1.57079632679 0 0" xyz="0 0 0.112"/>
   <axis xyz="0 0 1"/>
   <limit effort="5000" lower="-1.57079632679" upper="1.57079632679" velocity="3"/>
   <safety_controller k_position="100" k_velocity="2" soft_lower_limit="-1.53588974176" soft_upper_limit="1.53588974176"/>
   <dynamics damping="0.5"/>
 </joint>
 <link name="arm_link_2">
   <inertial>
     <origin rpy="0 0 0" xyz="0 -1.6810 0"/>
     <mass value="27"/>
     <inertia ixx="51.3" ixy="0" ixz="0" iyy="0.15" iyz="0" izz="51.3"/>
   </inertial>
   <visual>
     <origin rpy="1.57079632679 0 -1.57079632679" xyz="0 0 0"/>
     <geometry>
       <mesh filename="meshes_dISAS/arm/link_2.dae"/>
     </geometry>
     <material name="Grey"/>
   </visual>
   <stiffness name="rigid"/>
 </link>                       




 <!-- joint between link_2 and link_3 | 2_T_3 -->
<!-- <joint name="arm_joint_3" type="revolute">  -->
<joint name="arm_joint_3" type="revolute">
   <parent link="arm_link_2"/>
   <child link="arm_link_3"/>
   <origin rpy="0 0 3.14159265359" xyz="0 -3.36198 0"/>
   <axis xyz="0 0 1"/>
   <limit effort="5000" lower="-1.57079632679" upper="1.57079632679" velocity="3"/>
   <safety_controller k_position="100" k_velocity="2" soft_lower_limit="-1.53588974176" soft_upper_limit="1.53588974176"/>
   <dynamics damping="0.5"/>
 </joint>
 <link name="arm_link_3">
   <inertial>
     <origin rpy="0 0 0" xyz="0 0.0237 0"/>
     <mass value="7"/>
     <inertia ixx="0.021" ixy="0" ixz="0" iyy="0.01" iyz="0" izz="0.021"/>
   </inertial>
   <visual>
     <origin rpy="1.57079632679 0 0" xyz="0 0 0"/>
     <geometry>
       <mesh filename="meshes_dISAS/arm/link_3.dae"/>
     </geometry>
     <material name="Grey"/>
   </visual>
   <stiffness name="rigid"/>
 </link>                        



 <!-- joint between link_3 and link_4 | 3_T_4 -->
 <!-- <joint name="arm_joint_4" type="revolute">  -->
<joint name="arm_joint_4" type="revolute">
   <parent link="arm_link_3"/>
   <child link="arm_link_4"/>
   <origin rpy="1.57079632679 0 0" xyz="0 0.1125 0"/>
   <axis xyz="0 0 1"/>
   <limit effort="5000" lower="-3.14159265359" upper="3.14159265359" velocity="3"/>
   <safety_controller k_position="100" k_velocity="2" soft_lower_limit="-3.10668606855" soft_upper_limit="3.10668606855"/>
   <dynamics damping="0.5"/>
 </joint>
 <link name="arm_link_4"> 
   <inertial>
     <origin rpy="0 0 0" xyz="-1.1910 0 -0.2"/>
     <mass value="18"/>
     <inertia ixx="0.14" ixy="0" ixz="0" iyy="15.7" iyz="0" izz="15.7"/>
   </inertial>
   <visual>
     <origin rpy="0 0 3.14159265359" xyz="0 0 0"/>
     <geometry>
       <mesh filename="meshes_dISAS/arm/link_4.dae"/>
     </geometry>
     <material name="Grey"/>
   </visual>
   <stiffness name="rigid"/>
 </link>                             


 <!-- last joint -->
    <joint name="dlsaffe_joint_ee" type="fixed">
    <parent link="arm_link_4"/>
    <child link="dlsaffe_link_ee"/>
    <origin xyz="-2.5 0 -0.13" rpy="0 0 0"/>
    </joint>

    <link name="dlsaffe_link_ee">
      <inertial>
        <origin xyz="0 0 0" rpy="0 0 0"/>
        <mass value="0"/>
        <inertia ixx="0"  ixy="0"  ixz="0" iyy="0" iyz="0" izz="0" />
      </inertial>
      <visual>
        <origin xyz="0.05 0.05 0.05" rpy="0 0 0"/>
        <geometry>
          <box size="0.1 0.1 0.1"/>
        </geometry>
        <material name="Grey"/>
      </visual>
      <stiffness name="rigid"/>
    </link>


       <!-- last joint  -->
    <joint name="dlsaffe_joint_ee_tuile" type="fixed">
    <parent link="dlsaffe_link_ee"/>
    <child link="dlsaffe_link_ee_tuile"/>
    <origin xyz="0 0 0" rpy="0 0 0"/>
    </joint>  

    <link name="dlsaffe_link_ee_tuile">  
      <inertial>
        <origin xyz="0 0 0" rpy="0 0 0"/>
        <mass value="10"/>
        <inertia ixx="6"  ixy="0"  ixz="0" iyy="6" iyz="0" izz="6" />
      </inertial>
      <visual>
        <origin xyz="0 0 0" rpy="0 -1.570795*2 0"/>
        <geometry>
          <mesh filename="tile.stl"/>
        </geometry>
        <material name="Red"/>
      </visual>
      <stiffness name="rigid"/>
    </link>        


<!-- ********************************************************** -->
 <!-- ********************************************************** -->


 <!-- Airbus Arm -->


  <joint name="base_link-link0" type="fixed">
    <parent link="Payload"/>
    <child link="Link_0"/>
    <origin xyz="1.5 -1.6 0.76" rpy="pi/2 0 pi/2"/>
  <!--  <axis xyz="1 0 0"/>  -->
    <limit effort="1000.0" lower="0" upper="0" velocity="0"/>
    <!-- <origin xyz="0 0 0" rpy="0 0 ${2*C_1_DEGREE}"/> -->
  </joint>

  <link name="Link_0">
    <visual>
      <geometry>
        <mesh filename="meshes/Link0-DHReference-PublicRelease.stl"/>
      </geometry>
    </visual>
    <inertial>
      <mass value="0.627"/>
      <inertia ixx="0.00281845585208" ixy="0" ixz="0" iyy="0.00281883333333" iyz="0" izz="0.00379978918542"/>
      <origin xyz="0 0 0.0"/>
    </inertial>
    <stiffness name="rigid"/>
  </link>

   
  <joint name="Joint_1" type="revolute">
    <parent link="Link_0"/>
    <child link="Link_1"/>
    <axis xyz="0 0 1"/>
    <limit effort="50" lower="-3.14149265359" upper="3.14149265359" velocity="0.09395689"/>
    <origin xyz="0 0 0.18" rpy="0 0 0"/>
  </joint>

  <link name="Link_1">
    <visual>
      <geometry>
        <mesh filename="meshes/Link1-DHReference-PublicRelease.stl"/>
      </geometry>
    </visual>
    <inertial>
      <mass value="2.328"/>
      <inertia ixx="0.012" ixy="0" ixz="0" iyy="0.007" iyz="0.003" izz="0.008"/>
      <origin xyz="0 -0.029 -0.043"/>
    </inertial>    
    <stiffness name="rigid"/>
  </link>


  <joint name="Joint_2" type="revolute">
    <parent link="Link_1"/>
    <child link="Link_2"/>
    <axis xyz="0 0 1"/>
    <limit effort="50" lower="-3.14149265359" upper="3.14149265359" velocity="0.09395689"/>
    <origin xyz="0 0 0" rpy="1.57079632679 -1.57079632679 0"/>
  </joint>

 <link name="Link_2">
    <visual>
      <geometry>
        <mesh filename="meshes/Link2-DHReference-PublicRelease.stl"/>
      </geometry>
    </visual>
    <inertial>
      <mass value="3.995"/>
      <inertia ixx="0.010" ixy="0" ixz="0" iyy="0.578" iyz="0" izz="0.574"/>
      <origin xyz="0.4 0 0.142"/>
    </inertial>
    <stiffness name="rigid"/>
  </link>

 <joint name="Joint_3" type="revolute">
    <parent link="Link_2"/>
    <child link="Link_3"/>
    <axis xyz="0 0 1"/>
    <limit effort="50" lower="-3.14149265359" upper="3.14149265359" velocity="0.09395689"/>
    <origin xyz="0.8 0 0" rpy="0 0 -1.57079632679"/>
  </joint>

  <link name="Link_3">
    <visual>
      <geometry>
        <mesh filename="meshes/Link3-DHReference-PublicRelease.stl"/>
      </geometry>
    </visual>
    <inertial>
      <mass value="2.328"/>
      <inertia ixx="0.012" ixy="0" ixz="0" iyy="0.008" iyz="0.003" izz="0.007"/>
      <origin xyz="0 0.043 0.029"/>
    </inertial>
    <stiffness name="rigid"/>
  </link>

<joint name="Joint_4" type="revolute">
    <parent link="Link_3"/>
    <child link="Link_4"/>
    <axis xyz="0 0 1"/>
    <limit effort="50" lower="-3.14149265359" upper="3.14149265359" velocity="0.09395689"/>
    <origin xyz="0 0.65 0" rpy="-1.57079632679 0 0"/>
  </joint>


  <link name="Link_4">
    <visual>
      <geometry>
        <mesh filename="meshes/Link4-DHReference-PublicRelease.stl"/>
      </geometry>
    </visual>
    <inertial>
      <mass value="3.157"/>
      <inertia ixx="0.199" ixy="0" ixz="0" iyy="0.193" iyz="0.01" izz="0.01"/>
      <origin xyz="0 -0.043 -0.210"/>
    </inertial>
    <stiffness name="rigid"/>
  </link>

 <joint name="Joint_5" type="revolute">
    <parent link="Link_4"/>
    <child link="Link_5"/>
    <axis xyz="0 0 1"/>
    <limit effort="50" lower="-3.14149265359" upper="3.14149265359" velocity="0.09395689"/>
    <origin xyz="0 0 0" rpy="1.57079632679 0 0"/>
  </joint>


  <link name="Link_5">
    <visual>
      <geometry>
        <mesh filename="meshes/Link5-DHReference-PublicRelease.stl"/>
      </geometry>
    </visual>
    <inertial>
      <mass value="2.695"/>
      <inertia ixx="0.029" ixy="0" ixz="0" iyy="0.006" iyz="-0.001" izz="0.027"/>
      <origin xyz="0 0.125 -0.007"/>
    </inertial>
    <stiffness name="rigid"/>
  </link>

  
 
  <joint name="Joint_6" type="revolute">
    <parent link="Link_5"/>
    <child link="Link_6"/>
    <axis xyz="0 0 1"/>
    <limit effort="50" lower="-3.14149265359" upper="3.14149265359" velocity="0.09395689"/>
    <origin xyz="0 0.325 0" rpy="-1.57079632679 0 0"/>
  </joint>

  <link name="Link_6">
    <visual>
      <geometry>
        <mesh filename="meshes/Link6-DHReference-PublicRelease.stl"/>
      </geometry>
    </visual>
    <inertial>
      <mass value="0.924"/>
      <inertia ixx="0.002" ixy="0" ixz="0" iyy="0.002" iyz="0" izz="0.001"/>
      <origin xyz="0 0 0.0"/>
    </inertial>
    <stiffness name="rigid"/>
  </link>


</robot>
